2025-03-29 17:57:56,130 : INFO : root : Loading config.
2025-03-29 17:57:56,132 : INFO : YamlMultifileConfigLoader : Machine config file #1: config.yaml
2025-03-29 17:57:56,133 : WARNING : ConfigProcessor : Config file in cache changed: /home/pinpi/toedragons-pinball/config/config.yaml
2025-03-29 17:57:56,133 : INFO : ConfigProcessor : Loading config from file /home/pinpi/pinpi/lib/python3.11/site-packages/mpf/mpfconfig.yaml.
2025-03-29 17:57:56,179 : INFO : ConfigProcessor : Loading config: /home/pinpi/pinpi/lib/python3.11/site-packages/mpf/mpfconfig.yaml
2025-03-29 17:57:56,179 : INFO : ConfigProcessor : Loading config from file /home/pinpi/toedragons-pinball/config/config.yaml.
2025-03-29 17:57:56,184 : INFO : ConfigProcessor : Loading config: /home/pinpi/toedragons-pinball/config/config.yaml
2025-03-29 17:57:56,185 : INFO : ConfigProcessor : Config file cache created: /tmp/9121053a167b3a0609222a4623987891.mpf_cache
2025-03-29 17:57:56,219 : INFO : ConfigProcessor : Loading config from cache: /tmp/66ef204c87633dc02ca3efd475778ed9.mpf_cache
2025-03-29 17:57:56,219 : INFO : ConfigProcessor : Loading config from cache: /tmp/74f2825223a7abe8c76a0d15a1753cf2.mpf_cache
2025-03-29 17:57:56,220 : INFO : Machine : Mission Pinball Framework Core Engine v0.80.0.dev7
2025-03-29 17:57:56,220 : INFO : Machine : Command line arguments: {'no_load_cache': False, 'create_config_cache': True, 'bcp': False, 'configfile': ['config.yaml'], 'force_assets_load': False, 'platform_integration_test': False, 'jsonlogging': False, 'logfile': 'logs/2025-03-29-17-57-56-mpf-pinpi.log', 'pause': False, 'production': False, 'text_ui': True, 'loglevel': 15, 'consoleloglevel': 20, 'force_platform': None, 'syslog_address': None, 'full_logfile_path': '/home/pinpi/toedragons-pinball/logs/2025-03-29-17-57-56-mpf-pinpi.log'}
2025-03-29 17:57:56,220 : INFO : Machine : MPF path: /home/pinpi/pinpi/lib/python3.11/site-packages/mpf
2025-03-29 17:57:56,220 : INFO : Machine : Machine path: /home/pinpi/toedragons-pinball
2025-03-29 17:57:56,220 : INFO : Machine : Platform: linux
2025-03-29 17:57:56,220 : INFO : Machine : Python executable location: /home/pinpi/pinpi/bin/python
2025-03-29 17:57:56,220 : INFO : Machine : Python version: 3.11.2 (64-bit)
2025-03-29 17:57:56,221 : INFO : Machine : Initializing MPF...
2025-03-29 17:57:56,267 : INFO : FAST [NET] : Trying to connect to /dev/ttyAMA2 at 921600bps
2025-03-29 17:57:56,268 : INFO : FAST [NET] : Connected to /dev/ttyAMA2 at 921600bps
2025-03-29 17:57:56,270 : INFO : FAST [NET] : Connected to FP-CPU-2000 with firmware v02.26
2025-03-29 17:57:56,271 : INFO : FAST [NET] : Registered I/O Board 0: Model: FP-I/O-3208, Firmware: 01.10, Switches: 32, Drivers: 8
2025-03-29 17:57:56,271 : INFO : EventManager : Event: ======'machine_var_credits_string'====== Args={'value': 'FREE PLAY', 'prev_value': None, 'change': True}
2025-03-29 17:57:56,278 : INFO : EventManager : Event: ======'machine_var_master_volume'====== Args={'value': 0.5, 'prev_value': None, 'change': True}
2025-03-29 17:57:56,279 : INFO : EventManager : Event: ======'machine_var_mpf_version'====== Args={'value': 'Mission Pinball Framework v0.80.0.dev7', 'prev_value': None, 'change': True}
2025-03-29 17:57:56,279 : INFO : EventManager : Event: ======'machine_var_mpf_extended_version'====== Args={'value': 'Mission Pinball Framework v0.80.0.dev7, Config version:6, Show version: 6, BCP version:1.1', 'prev_value': None, 'change': True}
2025-03-29 17:57:56,279 : INFO : EventManager : Event: ======'machine_var_python_version'====== Args={'value': '3.11.2', 'prev_value': None, 'change': True}
2025-03-29 17:57:56,280 : INFO : EventManager : Event: ======'machine_var_platform'====== Args={'value': 'Linux-6.6.51+rpt-rpi-2712-aarch64-with-glibc2.36', 'prev_value': None, 'change': True}
2025-03-29 17:57:56,280 : INFO : EventManager : Event: ======'machine_var_platform_system'====== Args={'value': 'Linux', 'prev_value': None, 'change': True}
2025-03-29 17:57:56,280 : INFO : EventManager : Event: ======'machine_var_platform_release'====== Args={'value': '6.6.51+rpt-rpi-2712', 'prev_value': None, 'change': True}
2025-03-29 17:57:56,280 : INFO : EventManager : Event: ======'machine_var_platform_version'====== Args={'value': '#1 SMP PREEMPT Debian 1:6.6.51-1+rpt3 (2024-10-08)', 'prev_value': None, 'change': True}
2025-03-29 17:57:56,280 : INFO : EventManager : Event: ======'machine_var_platform_machine'====== Args={'value': 'aarch64', 'prev_value': None, 'change': True}
2025-03-29 17:57:56,280 : INFO : EventManager : Event: ======'machine_var_log_file_path'====== Args={'value': '/home/pinpi/toedragons-pinball/logs/2025-03-29-17-57-56-mpf-pinpi.log', 'prev_value': None, 'change': True}
2025-03-29 17:57:56,280 : INFO : EventManager : Event: ======'init_phase_1'====== Args={}
2025-03-29 17:57:56,286 : ERROR : asyncio : Task exception was never retrieved
future: <Task finished name='Task-15' coro=<SystemWideDevice.device_added_system_wide() done, defined at /home/pinpi/pinpi/lib/python3.11/site-packages/mpf/core/system_wide_device.py:15> exception=ValueError("invalid literal for int() with base 10: 'D1'")>
Traceback (most recent call last):
  File "/home/pinpi/pinpi/lib/python3.11/site-packages/mpf/core/system_wide_device.py", line 17, in device_added_system_wide
    await self._initialize()
  File "/home/pinpi/pinpi/lib/python3.11/site-packages/mpf/devices/driver.py", line 118, in _initialize
    self.hw_driver = self.platform.configure_driver(config, self.config['number'], platform_settings)
                     ^^^^^^^^^^^^^^^^^^^^^^^^^^^^^^^^^^^^^^^^^^^^^^^^^^^^^^^^^^^^^^^^^^^^^^^^^^^^^^^^
  File "/home/pinpi/pinpi/lib/python3.11/site-packages/mpf/platforms/fast/fast.py", line 389, in configure_driver
    index = self._parse_driver_number(number)
            ^^^^^^^^^^^^^^^^^^^^^^^^^^^^^^^^^
  File "/home/pinpi/pinpi/lib/python3.11/site-packages/mpf/platforms/fast/fast.py", line 344, in _parse_driver_number
    driver = int(driver_str)
             ^^^^^^^^^^^^^^^
ValueError: invalid literal for int() with base 10: 'D1'
2025-03-29 17:57:56,289 : ERROR : asyncio : Task exception was never retrieved
future: <Task finished name='Task-14' coro=<SystemWideDevice.device_added_system_wide() done, defined at /home/pinpi/pinpi/lib/python3.11/site-packages/mpf/core/system_wide_device.py:15> exception=ValueError("invalid literal for int() with base 10: 'D0'")>
Traceback (most recent call last):
  File "/home/pinpi/pinpi/lib/python3.11/site-packages/mpf/core/system_wide_device.py", line 17, in device_added_system_wide
    await self._initialize()
  File "/home/pinpi/pinpi/lib/python3.11/site-packages/mpf/devices/driver.py", line 118, in _initialize
    self.hw_driver = self.platform.configure_driver(config, self.config['number'], platform_settings)
                     ^^^^^^^^^^^^^^^^^^^^^^^^^^^^^^^^^^^^^^^^^^^^^^^^^^^^^^^^^^^^^^^^^^^^^^^^^^^^^^^^
  File "/home/pinpi/pinpi/lib/python3.11/site-packages/mpf/platforms/fast/fast.py", line 389, in configure_driver
    index = self._parse_driver_number(number)
            ^^^^^^^^^^^^^^^^^^^^^^^^^^^^^^^^^
  File "/home/pinpi/pinpi/lib/python3.11/site-packages/mpf/platforms/fast/fast.py", line 344, in _parse_driver_number
    driver = int(driver_str)
             ^^^^^^^^^^^^^^^
ValueError: invalid literal for int() with base 10: 'D0'
2025-03-29 17:57:56,290 : INFO : Machine : Starting the main run loop with active modes: []
2025-03-29 17:57:56,290 : WARNING : Machine : Attract mode is not active, game will not be playable. Please check your attract mode configuration.
2025-03-29 17:57:56,290 : INFO : Machine : Shutting down...
2025-03-29 17:57:56,290 : INFO : EventManager : Event: ======'shutdown'====== Args={}
2025-03-29 17:57:56,361 : INFO : EventManager : Event: ======'init_phase_2'====== Args={}
2025-03-29 17:57:56,365 : INFO : EventManager : Event: ======'init_phase_3'====== Args={}
2025-03-29 17:57:56,366 : INFO : EventManager : Event: ======'init_phase_4'====== Args={}
2025-03-29 17:57:56,367 : ERROR : asyncio : Exception in callback EventManager._queue_task_done(<Task finishe...te 'number'")>)
handle: <Handle EventManager._queue_task_done(<Task finishe...te 'number'")>)>
Traceback (most recent call last):
  File "/usr/lib/python3.11/asyncio/events.py", line 80, in _run
    self._context.run(self._callback, *self._args)
  File "/home/pinpi/pinpi/lib/python3.11/site-packages/mpf/core/events.py", line 795, in _queue_task_done
    future.result()
  File "/home/pinpi/pinpi/lib/python3.11/site-packages/mpf/core/events.py", line 708, in _run_handlers_sequential
    handler.callback(queue=queue, **merged_kwargs)
  File "/home/pinpi/pinpi/lib/python3.11/site-packages/mpf/devices/driver.py", line 56, in _check_duplicate_coil_numbers
    key = (coil.config['platform'], coil.hw_driver.number)
                                    ^^^^^^^^^^^^^^^^^^^^^
AttributeError: 'NoneType' object has no attribute 'number'
2025-03-29 17:57:57,394 : ERROR : Machine : Runtime Exception
Traceback (most recent call last):
  File "/home/pinpi/pinpi/lib/python3.11/site-packages/mpf/core/machine.py", line 808, in _run_loop
    raise self._exception['exception']
  File "/home/pinpi/pinpi/lib/python3.11/site-packages/mpf/core/system_wide_device.py", line 17, in device_added_system_wide
    await self._initialize()
  File "/home/pinpi/pinpi/lib/python3.11/site-packages/mpf/devices/driver.py", line 118, in _initialize
    self.hw_driver = self.platform.configure_driver(config, self.config['number'], platform_settings)
                     ^^^^^^^^^^^^^^^^^^^^^^^^^^^^^^^^^^^^^^^^^^^^^^^^^^^^^^^^^^^^^^^^^^^^^^^^^^^^^^^^
  File "/home/pinpi/pinpi/lib/python3.11/site-packages/mpf/platforms/fast/fast.py", line 389, in configure_driver
    index = self._parse_driver_number(number)
            ^^^^^^^^^^^^^^^^^^^^^^^^^^^^^^^^^
  File "/home/pinpi/pinpi/lib/python3.11/site-packages/mpf/platforms/fast/fast.py", line 344, in _parse_driver_number
    driver = int(driver_str)
             ^^^^^^^^^^^^^^^
ValueError: invalid literal for int() with base 10: 'D1'
2025-03-29 17:57:57,396 : INFO : root : MPF run loop ended.
