2025-03-26 09:54:38,576 : INFO : root : Loading config.
2025-03-26 09:54:38,578 : INFO : YamlMultifileConfigLoader : Machine config file #1: config.yaml
2025-03-26 09:54:38,579 : WARNING : ConfigProcessor : Config file in cache changed: /home/pinpi/toedragons-pinball/config/config.yaml
2025-03-26 09:54:38,579 : INFO : ConfigProcessor : Loading config from file /home/pinpi/pinpi/lib/python3.11/site-packages/mpf/mpfconfig.yaml.
2025-03-26 09:54:38,625 : INFO : ConfigProcessor : Loading config: /home/pinpi/pinpi/lib/python3.11/site-packages/mpf/mpfconfig.yaml
2025-03-26 09:54:38,625 : INFO : ConfigProcessor : Loading config from file /home/pinpi/toedragons-pinball/config/config.yaml.
2025-03-26 09:54:38,630 : INFO : ConfigProcessor : Loading config: /home/pinpi/toedragons-pinball/config/config.yaml
2025-03-26 09:54:38,631 : INFO : ConfigProcessor : Config file cache created: /tmp/9121053a167b3a0609222a4623987891.mpf_cache
2025-03-26 09:54:38,663 : INFO : ConfigProcessor : Loading config from cache: /tmp/66ef204c87633dc02ca3efd475778ed9.mpf_cache
2025-03-26 09:54:38,664 : INFO : ConfigProcessor : Loading config from cache: /tmp/74f2825223a7abe8c76a0d15a1753cf2.mpf_cache
2025-03-26 09:54:38,664 : INFO : Machine : Mission Pinball Framework Core Engine v0.80.0.dev7
2025-03-26 09:54:38,664 : INFO : Machine : Command line arguments: {'no_load_cache': False, 'create_config_cache': True, 'bcp': False, 'configfile': ['config.yaml'], 'force_assets_load': False, 'platform_integration_test': False, 'jsonlogging': False, 'logfile': 'logs/2025-03-26-09-54-38-mpf-pinpi.log', 'pause': False, 'production': False, 'text_ui': False, 'loglevel': 15, 'consoleloglevel': 20, 'force_platform': None, 'syslog_address': None, 'full_logfile_path': '/home/pinpi/toedragons-pinball/logs/2025-03-26-09-54-38-mpf-pinpi.log'}
2025-03-26 09:54:38,664 : INFO : Machine : MPF path: /home/pinpi/pinpi/lib/python3.11/site-packages/mpf
2025-03-26 09:54:38,664 : INFO : Machine : Machine path: /home/pinpi/toedragons-pinball
2025-03-26 09:54:38,664 : INFO : Machine : Platform: linux
2025-03-26 09:54:38,664 : INFO : Machine : Python executable location: /home/pinpi/pinpi/bin/python
2025-03-26 09:54:38,665 : INFO : Machine : Python version: 3.11.2 (64-bit)
2025-03-26 09:54:38,666 : INFO : Machine : Initializing MPF...
2025-03-26 09:54:38,700 : INFO : FAST [NET] : Trying to connect to /dev/ttyAMA2 at 921600bps
2025-03-26 09:54:38,701 : INFO : FAST [NET] : Connected to /dev/ttyAMA2 at 921600bps
2025-03-26 09:54:38,703 : INFO : FAST [NET] : Connected to FP-CPU-2000 with firmware v02.26
2025-03-26 09:54:38,703 : INFO : EventManager : Event: ======'machine_var_credits_string'====== Args={'value': 'FREE PLAY', 'prev_value': None, 'change': True}
2025-03-26 09:54:38,712 : INFO : EventManager : Event: ======'machine_var_master_volume'====== Args={'value': 0.5, 'prev_value': None, 'change': True}
2025-03-26 09:54:38,712 : INFO : EventManager : Event: ======'machine_var_mpf_version'====== Args={'value': 'Mission Pinball Framework v0.80.0.dev7', 'prev_value': None, 'change': True}
2025-03-26 09:54:38,712 : INFO : EventManager : Event: ======'machine_var_mpf_extended_version'====== Args={'value': 'Mission Pinball Framework v0.80.0.dev7, Config version:6, Show version: 6, BCP version:1.1', 'prev_value': None, 'change': True}
2025-03-26 09:54:38,712 : INFO : EventManager : Event: ======'machine_var_python_version'====== Args={'value': '3.11.2', 'prev_value': None, 'change': True}
2025-03-26 09:54:38,714 : INFO : EventManager : Event: ======'machine_var_platform'====== Args={'value': 'Linux-6.6.51+rpt-rpi-2712-aarch64-with-glibc2.36', 'prev_value': None, 'change': True}
2025-03-26 09:54:38,714 : INFO : EventManager : Event: ======'machine_var_platform_system'====== Args={'value': 'Linux', 'prev_value': None, 'change': True}
2025-03-26 09:54:38,714 : INFO : EventManager : Event: ======'machine_var_platform_release'====== Args={'value': '6.6.51+rpt-rpi-2712', 'prev_value': None, 'change': True}
2025-03-26 09:54:38,714 : INFO : EventManager : Event: ======'machine_var_platform_version'====== Args={'value': '#1 SMP PREEMPT Debian 1:6.6.51-1+rpt3 (2024-10-08)', 'prev_value': None, 'change': True}
2025-03-26 09:54:38,714 : INFO : EventManager : Event: ======'machine_var_platform_machine'====== Args={'value': 'aarch64', 'prev_value': None, 'change': True}
2025-03-26 09:54:38,714 : INFO : EventManager : Event: ======'machine_var_log_file_path'====== Args={'value': '/home/pinpi/toedragons-pinball/logs/2025-03-26-09-54-38-mpf-pinpi.log', 'prev_value': None, 'change': True}
2025-03-26 09:54:38,714 : INFO : EventManager : Event: ======'init_phase_1'====== Args={}
2025-03-26 09:54:38,721 : ERROR : asyncio : Task exception was never retrieved
future: <Task finished name='Task-17' coro=<SystemWideDevice.device_added_system_wide() done, defined at /home/pinpi/pinpi/lib/python3.11/site-packages/mpf/core/system_wide_device.py:15> exception=ConfigFileError('Failed to configure switch s_left_flipper in platform. See error above')>
Traceback (most recent call last):
  File "/home/pinpi/pinpi/lib/python3.11/site-packages/mpf/platforms/fast/fast.py", line 470, in _parse_switch_number
    board_str, switch_str = number.split("-")
    ^^^^^^^^^^^^^^^^^^^^^
ValueError: not enough values to unpack (expected 2, got 1)

The above exception was the direct cause of the following exception:

Traceback (most recent call last):
  File "/home/pinpi/pinpi/lib/python3.11/site-packages/mpf/devices/switch.py", line 149, in _initialize
    self.hw_switch = self.platform.configure_switch(
                     ^^^^^^^^^^^^^^^^^^^^^^^^^^^^^^^
  File "/home/pinpi/pinpi/lib/python3.11/site-packages/mpf/platforms/fast/fast.py", line 542, in configure_switch
    number = self._parse_switch_number(number)
             ^^^^^^^^^^^^^^^^^^^^^^^^^^^^^^^^^
  File "/home/pinpi/pinpi/lib/python3.11/site-packages/mpf/platforms/fast/fast.py", line 478, in _parse_switch_number
    raise AssertionError(f"Switch {int(index, 16)} does not exist. Only "
AssertionError: Switch 0 does not exist. Only 0 switches found. Switch number: 0

The above exception was the direct cause of the following exception:

Traceback (most recent call last):
  File "/home/pinpi/pinpi/lib/python3.11/site-packages/mpf/core/system_wide_device.py", line 17, in device_added_system_wide
    await self._initialize()
  File "/home/pinpi/pinpi/lib/python3.11/site-packages/mpf/devices/switch.py", line 152, in _initialize
    raise ConfigFileError("Failed to configure switch {} in platform. See error above".format(self.name), 2,
mpf.exceptions.config_file_error.ConfigFileError: Config File Error in switch: Failed to configure switch s_left_flipper in platform. See error above Error Code: CFE-switch-2 (https://missionpinball.org/logs)
2025-03-26 09:54:38,722 : ERROR : asyncio : Task exception was never retrieved
future: <Task finished name='Task-18' coro=<SystemWideDevice.device_added_system_wide() done, defined at /home/pinpi/pinpi/lib/python3.11/site-packages/mpf/core/system_wide_device.py:15> exception=ConfigFileError('Failed to configure switch s_right_flipper in platform. See error above')>
Traceback (most recent call last):
  File "/home/pinpi/pinpi/lib/python3.11/site-packages/mpf/platforms/fast/fast.py", line 470, in _parse_switch_number
    board_str, switch_str = number.split("-")
    ^^^^^^^^^^^^^^^^^^^^^
ValueError: not enough values to unpack (expected 2, got 1)

The above exception was the direct cause of the following exception:

Traceback (most recent call last):
  File "/home/pinpi/pinpi/lib/python3.11/site-packages/mpf/devices/switch.py", line 149, in _initialize
    self.hw_switch = self.platform.configure_switch(
                     ^^^^^^^^^^^^^^^^^^^^^^^^^^^^^^^
  File "/home/pinpi/pinpi/lib/python3.11/site-packages/mpf/platforms/fast/fast.py", line 542, in configure_switch
    number = self._parse_switch_number(number)
             ^^^^^^^^^^^^^^^^^^^^^^^^^^^^^^^^^
  File "/home/pinpi/pinpi/lib/python3.11/site-packages/mpf/platforms/fast/fast.py", line 478, in _parse_switch_number
    raise AssertionError(f"Switch {int(index, 16)} does not exist. Only "
AssertionError: Switch 1 does not exist. Only 0 switches found. Switch number: 1

The above exception was the direct cause of the following exception:

Traceback (most recent call last):
  File "/home/pinpi/pinpi/lib/python3.11/site-packages/mpf/core/system_wide_device.py", line 17, in device_added_system_wide
    await self._initialize()
  File "/home/pinpi/pinpi/lib/python3.11/site-packages/mpf/devices/switch.py", line 152, in _initialize
    raise ConfigFileError("Failed to configure switch {} in platform. See error above".format(self.name), 2,
mpf.exceptions.config_file_error.ConfigFileError: Config File Error in switch: Failed to configure switch s_right_flipper in platform. See error above Error Code: CFE-switch-2 (https://missionpinball.org/logs)
2025-03-26 09:54:38,723 : INFO : Machine : Starting the main run loop with active modes: []
2025-03-26 09:54:38,723 : WARNING : Machine : Attract mode is not active, game will not be playable. Please check your attract mode configuration.
2025-03-26 09:54:38,723 : INFO : Machine : Shutting down...
2025-03-26 09:54:38,723 : INFO : EventManager : Event: ======'shutdown'====== Args={}
2025-03-26 09:54:38,793 : ERROR : asyncio : Exception in callback Util.raise_exceptions(<Task finishe...te 'number'")>) at /home/pinpi/pinpi/lib/python3.11/site-packages/mpf/core/utility_functions.py:789
handle: <Handle Util.raise_exceptions(<Task finishe...te 'number'")>) at /home/pinpi/pinpi/lib/python3.11/site-packages/mpf/core/utility_functions.py:789>
Traceback (most recent call last):
  File "/usr/lib/python3.11/asyncio/events.py", line 80, in _run
    self._context.run(self._callback, *self._args)
  File "/home/pinpi/pinpi/lib/python3.11/site-packages/mpf/core/utility_functions.py", line 797, in raise_exceptions
    future.result()
  File "/home/pinpi/pinpi/lib/python3.11/site-packages/mpf/platforms/fast/communicators/base.py", line 413, in _socket_reader
    self.parse_incoming_raw_bytes(resp)
  File "/home/pinpi/pinpi/lib/python3.11/site-packages/mpf/platforms/fast/communicators/base.py", line 373, in parse_incoming_raw_bytes
    self._dispatch_incoming_msg(msg)
  File "/home/pinpi/pinpi/lib/python3.11/site-packages/mpf/platforms/fast/communicators/base.py", line 382, in _dispatch_incoming_msg
    self.message_processors[msg_header](msg[3:])
  File "/home/pinpi/pinpi/lib/python3.11/site-packages/mpf/platforms/fast/communicators/net_neuron.py", line 290, in _process_sa
    self.update_switches_from_hw_data()
  File "/home/pinpi/pinpi/lib/python3.11/site-packages/mpf/platforms/fast/communicators/net_neuron.py", line 300, in update_switches_from_hw_data
    hw_state = self.platform.hw_switch_data[switch.hw_switch.number]
                                            ^^^^^^^^^^^^^^^^^^^^^^^
AttributeError: 'NoneType' object has no attribute 'number'
2025-03-26 09:54:39,826 : ERROR : Machine : Runtime Exception
Traceback (most recent call last):
  File "/home/pinpi/pinpi/lib/python3.11/site-packages/mpf/platforms/fast/fast.py", line 470, in _parse_switch_number
    board_str, switch_str = number.split("-")
    ^^^^^^^^^^^^^^^^^^^^^
ValueError: not enough values to unpack (expected 2, got 1)

The above exception was the direct cause of the following exception:

Traceback (most recent call last):
  File "/home/pinpi/pinpi/lib/python3.11/site-packages/mpf/devices/switch.py", line 149, in _initialize
    self.hw_switch = self.platform.configure_switch(
                     ^^^^^^^^^^^^^^^^^^^^^^^^^^^^^^^
  File "/home/pinpi/pinpi/lib/python3.11/site-packages/mpf/platforms/fast/fast.py", line 542, in configure_switch
    number = self._parse_switch_number(number)
             ^^^^^^^^^^^^^^^^^^^^^^^^^^^^^^^^^
  File "/home/pinpi/pinpi/lib/python3.11/site-packages/mpf/platforms/fast/fast.py", line 478, in _parse_switch_number
    raise AssertionError(f"Switch {int(index, 16)} does not exist. Only "
AssertionError: Switch 0 does not exist. Only 0 switches found. Switch number: 0

The above exception was the direct cause of the following exception:

Traceback (most recent call last):
  File "/home/pinpi/pinpi/lib/python3.11/site-packages/mpf/core/machine.py", line 808, in _run_loop
    raise self._exception['exception']
  File "/home/pinpi/pinpi/lib/python3.11/site-packages/mpf/core/system_wide_device.py", line 17, in device_added_system_wide
    await self._initialize()
  File "/home/pinpi/pinpi/lib/python3.11/site-packages/mpf/devices/switch.py", line 152, in _initialize
    raise ConfigFileError("Failed to configure switch {} in platform. See error above".format(self.name), 2,
mpf.exceptions.config_file_error.ConfigFileError: Config File Error in switch: Failed to configure switch s_left_flipper in platform. See error above Error Code: CFE-switch-2 (https://missionpinball.org/logs)
2025-03-26 09:54:39,827 : INFO : root : MPF run loop ended.
