2025-03-26 09:46:21,528 : INFO : root : Loading config.
2025-03-26 09:46:21,530 : INFO : YamlMultifileConfigLoader : Machine config file #1: config.yaml
2025-03-26 09:46:21,530 : INFO : ConfigProcessor : Loading config from cache: /tmp/9121053a167b3a0609222a4623987891.mpf_cache
2025-03-26 09:46:21,564 : INFO : ConfigProcessor : Loading config from cache: /tmp/66ef204c87633dc02ca3efd475778ed9.mpf_cache
2025-03-26 09:46:21,564 : INFO : ConfigProcessor : Loading config from cache: /tmp/74f2825223a7abe8c76a0d15a1753cf2.mpf_cache
2025-03-26 09:46:21,564 : INFO : Machine : Mission Pinball Framework Core Engine v0.80.0.dev7
2025-03-26 09:46:21,564 : INFO : Machine : Command line arguments: {'no_load_cache': False, 'create_config_cache': True, 'bcp': False, 'configfile': ['config.yaml'], 'force_assets_load': False, 'platform_integration_test': False, 'jsonlogging': False, 'logfile': 'logs/2025-03-26-09-46-21-mpf-pinpi.log', 'pause': False, 'production': False, 'text_ui': True, 'loglevel': 15, 'consoleloglevel': 20, 'force_platform': None, 'syslog_address': None, 'full_logfile_path': '/home/pinpi/toedragons-pinball/logs/2025-03-26-09-46-21-mpf-pinpi.log'}
2025-03-26 09:46:21,564 : INFO : Machine : MPF path: /home/pinpi/pinpi/lib/python3.11/site-packages/mpf
2025-03-26 09:46:21,564 : INFO : Machine : Machine path: /home/pinpi/toedragons-pinball
2025-03-26 09:46:21,565 : INFO : Machine : Platform: linux
2025-03-26 09:46:21,565 : INFO : Machine : Python executable location: /home/pinpi/pinpi/bin/python
2025-03-26 09:46:21,565 : INFO : Machine : Python version: 3.11.2 (64-bit)
2025-03-26 09:46:21,565 : INFO : Machine : Initializing MPF...
2025-03-26 09:46:21,607 : INFO : FAST [NET] : Trying to connect to /dev/ttyAMA2 at 921600bps
2025-03-26 09:46:21,607 : ERROR : FAST [NET] : Failed to connect to any of the specified ports.
2025-03-26 09:46:21,608 : INFO : Machine : Shutting down...
2025-03-26 09:46:21,608 : INFO : EventManager : Event: ======'shutdown'====== Args={}
2025-03-26 09:46:21,708 : ERROR : Machine : Failed to initialize MPF
Traceback (most recent call last):
  File "/home/pinpi/pinpi/lib/python3.11/site-packages/mpf/platforms/fast/fast.py", line 279, in _connect_to_hardware
    await communicator.connect()
  File "/home/pinpi/pinpi/lib/python3.11/site-packages/mpf/platforms/fast/communicators/base.py", line 114, in connect
    raise SerialException(f"{self} could not connect to a serial port. Is it open in CoolTerm? ;)")
serial.serialutil.SerialException: [FAST NET] could not connect to a serial port. Is it open in CoolTerm? ;)

The above exception was the direct cause of the following exception:

Traceback (most recent call last):
  File "/home/pinpi/pinpi/lib/python3.11/site-packages/mpf/core/machine.py", line 686, in initialize_mpf
    raise init.exception()
  File "/home/pinpi/pinpi/lib/python3.11/site-packages/mpf/core/machine.py", line 248, in initialize
    await self.initialize_core_and_hardware()
  File "/home/pinpi/pinpi/lib/python3.11/site-packages/mpf/core/machine.py", line 244, in initialize_core_and_hardware
    await self._initialize_platforms()
  File "/home/pinpi/pinpi/lib/python3.11/site-packages/mpf/core/machine.py", line 334, in _initialize_platforms
    result.result()
  File "/home/pinpi/pinpi/lib/python3.11/site-packages/mpf/platforms/fast/fast.py", line 125, in initialize
    await self._connect_to_hardware()
  File "/home/pinpi/pinpi/lib/python3.11/site-packages/mpf/platforms/fast/fast.py", line 286, in _connect_to_hardware
    raise MpfRuntimeError(f"Could not open serial port {port}. Is something else connected to the port? "
mpf.exceptions.runtime_error.MpfRuntimeError: Runtime Error in FAST: Could not open serial port net. Is something else connected to the port? Did the port number or your computer change? Do you have permissions to access the port? Error Code: RE-FAST-1 (https://missionpinball.org/logs)
2025-03-26 09:46:21,710 : INFO : root : MPF run loop ended.
